Workbook

Sheet Deal ledger
O1: Row identity | Q1: Count | R1: Dates | W1: Price | AB1: Settlement | AD1: Conditions detail | AE1: Deadline & finality | AH1: Outcome | AK1: Source page | AL1: Related rows | AM1: Deal
A2: # | B2: When | C2: Who | D2: What happened | E2: Process | F2: Round | G2: Type | H2: Terms or outcome | I2: Formality | J2: Conditions level | K2: Why and evidence | L2: Source | M2: Review | N2: Reviewer note | O2: Row id | P2: Include | Q2: Count | R2: Date from | S2: Date to | T2: Working date | U2: Date basis | V2: Date method | W2: Price low | X2: Price high | Y2: Price kind | Z2: Price origin | AA2: Currency | AB2: All cash | AC2: Cash at closing | AD2: Conditions detail | AE2: Due date | AF2: Deadline treatment | AG2: Round finality | AH2: Decided by | AI2: Exit reason | AJ2: Outcome basis | AK2: Page | AL2: Related rows | AM2: Deal
A3: 1 | B3: Q4 2015 (calendar quarter) | C3: Party A (one of the Company’s Class I rail partners) | D3: Bidder interest | E3: 1 | F3: 0 | G3: Strategic | H3: Unpriced approach: Party A suggested possible joint venture arrangements and expressed interest in acquiring equity in the Company to develop strategic opportunities and enhance regional connectivity; scope as to control not specified (not treated as a whole-company bid); first sale-related contact, bidder-initiated, with the Chairman/CEO and the VP & Chief Commercial Officer; prompted the Board to form an investment-banker subcommittee. Count 1 = newly represented first-contact party (the contact fact is carried here; see Summary contact tally). | K3: Bidder interest (stated): the filing reports an unpriced expression of interest in acquiring equity, not a priced proposal, and no per-share or aggregate value exists for it. Direction: bidder-to-target. Quote: “In the fourth quarter of 2015, Robert H. Eder (the Company’s Chairman and Chief Executive Officer) and Frank K. Rogers (the Company’s Vice President and Chief Commercial Officer) met with one of the Company’s Class I rail partners (“Party A”) to discuss joint commercial opportunities. During the meeting, Party A suggested possible joint venture arrangements and expressed some interest in acquiring equity in the Company to further develop strategic opportunities and enhance regional connectivity” | L3: =HYPERLINK("#Source text!$D$2","P-001 (main: P-001)") | M3: Q5 | O3: R001 | P3: Yes | Q3: 1 | R3: 2015-10-01 | S3: 2015-12-31 | T3: 2015-11-15 | U3: Reported interval | V3: Assigned: midpoint | AK3: 27 | AM3: PWRR-G&W 2016
A4: 2 | B4: 01/27/2016 | C4: GHF (Greene Holcomb & Fisher LLC) — Company financial adviser; later BMO | D4: Adviser engaged | E4: 1 | F4: 0 | H4: Engaged as the Company’s investment banking firm: subcommittee recommendation approved at the 01/27/2016 executive session (Director Smith absent); GHF presented its qualifications and a proposed change-in-control process; represented it would not represent any potential buyer of the Company or any person proposing financing for such an offer; engagement followed the late-2015 banker interviews. GHF’s business was acquired by BMO Capital Markets Corp. on 08/01/2016 — the same adviser relationship continued as BMO (no second adviser row); aggregate fee ~$2.52 million. | K4: Adviser engaged (stated): engagement approval on the stated day; the engagement-letter date is not disclosed. The GHF-to-BMO acquisition is a firm change, not a new mandate (section 5.4). Quotes: “the subcommittee recommended to the Board that the Company retain GHF as its investment banking firm. At that meeting, representatives of GHF discussed with the Board its qualifications and a proposed process should the directors ultimately decide to proceed with a change in control transaction. As part of the interview process, GHF represented to the Company that it would not represent any potential buyer of the Company in connection with an offer to purchase the Company or any person proposing to provide financing in connection with such an offer. Following this presentation, the Board approved the subcommittee’s recommendation and the Company engaged GHF” / “GHF represented to the Company that it would not represent any potential buyer of the Company in connection with an offer to purchase the Company or any person proposing to provide financing in connection with such an offer” Fee: “the Company will pay BMO an aggregate fee of approximately $2.52 million”, the remainder and majority payable upon consummation (X-015). | L4: =HYPERLINK("#Source text!$D$2","P-001; X-015 (main: P-001)") | O4: R002 | P4: Yes | R4: 2016-01-27 | S4: 2016-01-27 | T4: 2016-01-27 | U4: Reported day | V4: Reported | AK4: 27 | AL4: mandate continued as BMO from 08/01/2016 (Summary advisers) | AM4: PWRR-G&W 2016
A5: 3 | B5: 03/14/2016 | C5: Board of Directors (special meeting) | D5: Target sale decision | E5: 1 | F5: 0 | H5: Decided to proceed with GHF’s proposed process: discussions with Party A plus solicitation of other third parties regarding a change in control transaction; qualified as an exploratory strategy, not a commitment to sell; appointed the Transaction Committee (Barrett (Chair), Anderson, Garvey) to supervise the process and recommend to the full Board; the Committee could not itself approve a change of control. | K5: Target sale decision (stated): “Representatives of GHF then proposed a process pursuant to which the Company would proceed with discussions with Party A and also solicit interest from other potential third parties regarding a change in control transaction” The qualification (exploratory strategy) is preserved. Committee appointment: “the Board appointed a special committee of independent directors of the Board (which we refer to as the “Transaction Committee”), composed of Frank W. Barrett (Chair), Richard W. Anderson and James C. Garvey, for the purpose of assisting in the supervision and oversight of the process on the full Board’s behalf and making a recommendation to the full Board” | L5: =HYPERLINK("#Source text!$D$3","P-002 (main: P-002)") | M5: Q1 | O5: R003 | P5: Yes | R5: 2016-03-14 | S5: 2016-03-14 | T5: 2016-03-14 | U5: Reported day | V5: Reported | AK5: 27 | AL5: candidate R1 anchor (rejected); R005 | AM5: PWRR-G&W 2016
A6: 4 | B6: 03/22/2016–03/23/2016 | C6: Party A | D6: Contact | E6: 1 | F6: 0 | G6: Strategic | H6: Management (CFO/Treasurer Noreck and other senior managers) met Party A representatives and informed Party A of GHF’s engagement. Repeat contact: Party A was already in contact from Q4 2015, so Count 0 (no double counting). | K6: Contact (stated), repeat within the process. Quotes: “On March 22, 2016 and March 23, 2016, Daniel T. Noreck (the Company’s Chief Financial Officer and Treasurer) and other members of the senior management team of the Company met with various representatives of Party A” / “met with various representatives of Party A on March 22 and 23, 2016 and had informed Party A of GHF’s engagement” A two-day series of meetings takes its first day as the Working date. | L6: =HYPERLINK("#Source text!$D$4","P-003; P-004 (main: P-003)") | O6: R004 | P6: Yes | Q6: 0 | R6: 2016-03-22 | S6: 2016-03-23 | T6: 2016-03-22 | U6: Reported interval | V6: Assigned: bound | AK6: 28 | AL6: first contact R001 | AM6: PWRR-G&W 2016
A7: 5 | B7: 03/24/2016 | C7: Transaction Committee | D7: Target decision | E7: 1 | F7: 0 | H7: Authorized GHF to contact Party A and other potential buyers to determine their interest in a change in control transaction. Candidate anchor for Round 1, rejected: an authorization to approach firms is not the completed outreach (the actual first wave is R007). | K7: Target decision (stated): “The Transaction Committee authorized GHF to contact Party A as well as other potential buyers to determine their level of interest in a change in control transaction” Kept as a rejected R1 anchor row so the boundary can be moved. | L7: =HYPERLINK("#Source text!$D$5","P-004 (main: P-004)") | M7: Q1 | O7: R005 | P7: Yes | R7: 2016-03-24 | S7: 2016-03-24 | T7: 2016-03-24 | U7: Reported day | V7: Reported | AK7: 28 | AL7: candidate R1 anchor (rejected); R007; R008 | AM7: PWRR-G&W 2016
A8: 6 | B8: 03/24/2016 | C8: Hinckley, Allen & Snyder LLP (Hinckley Allen) — Company legal counsel | D8: Adviser service observed | E8: 1 | F8: 0 | H8: Company legal counsel; participated in all Transaction Committee meetings; engagement date not disclosed; first shown acting 03/24/2016. | K8: Adviser service observed (stated): the filing shows Hinckley Allen already providing services on 03/24/2016; no selection or engagement date is disclosed, so the Working date is the earliest date shown acting. Quote: “representatives of each of GHF and the Company’s legal counsel, Hinckley, Allen & Snyder LLP (which we refer to as “Hinckley Allen”), participated in all meetings of the Transaction Committee” | L8: =HYPERLINK("#Source text!$D$5","P-004 (main: P-004)") | O8: R006 | P8: Yes | R8: 2016-03-24 | S8: 2016-03-24 | T8: 2016-03-24 | U8: Reported day | V8: Reported | AK8: 28 | AM8: PWRR-G&W 2016
A9: 7 | B9: week of 03/28/2016 | C9: 29 potential buyers (11 strategic incl. Party A; 18 financial) | D9: Contact | E9: 1 | F9: 1 | G9: Unknown | H9: First outreach wave: GHF contacted 11 potential strategic buyers (including Party A) and 18 potential financial buyers in accordance with the Transaction Committee’s directives; Count 29 = disclosed cohort size (includes Party A, already in contact since Q4 2015). Type: Unknown — the cohort mixes strategic and financial buyers (split supplied only for the signing wave, R009–R011). | K9: Contact (stated cohort, executed outreach). Quote: “During the week of March 28, 2016, in accordance with the Transaction Committee’s directives, representatives of GHF contacted 11 potential strategic buyers (including Party A) and 18 potential financial buyers” This is the R1 anchor event (see R008). | L9: =HYPERLINK("#Source text!$D$5","P-004 (main: P-004)") | M9: Q1 | O9: R007 | P9: Yes | Q9: 29 | R9: 2016-03-28 | S9: 2016-04-03 | T9: 2016-03-28 | U9: Reported interval | V9: Assigned: bound | AK9: 28 | AL9: R008 (anchor event) | AM9: PWRR-G&W 2016
A10: 8 | B10: week of 03/28/2016 | C10: Process (Round 1) | D10: Round opened | E10: 1 | F10: 1 | H10: R1 anchor: first outreach wave — GHF contacted 11 potential strategic buyers (including Party A) and 18 potential financial buyers (R007); candidate anchors: R003 (03/14/2016 sale-strategy decision), R005 (03/24/2016 authorization to contact). Objective: solicit change-in-control interest and confirm the continuing interest of NDA signers; the round runs through the IOI stage to the 06/01/2016 advancement decision. Round finality: Not final — no final/binding/best-and-final announcement and no move to definitive negotiation; the stage closed by selection to management presentations (R021). | K10: Round opened (convention/analytical). First outreach wave chosen under section 6.3(1); R003 and R005 are the retained rejected candidate anchors. Quote: “During the week of March 28, 2016, in accordance with the Transaction Committee’s directives, representatives of GHF contacted 11 potential strategic buyers (including Party A) and 18 potential financial buyers” | L10: =HYPERLINK("#Source text!$D$5","P-004 (main: P-004)") | M10: Q1 | O10: R008 | P10: Yes | R10: 2016-03-28 | S10: 2016-04-03 | T10: 2016-03-28 | U10: Reported interval | V10: Assigned: bound | AG10: Not final | AK10: 28 | AL10: anchor R007; candidates R003, R005 | AM10: PWRR-G&W 2016
A11: 9 | B11: from the week of 03/28/2016; by 04/22/2016 | C11: 10 remaining potential strategic buyers (11 contacted less G&W) | D11: NDA signed | E11: 1 | F11: 1 | G11: Strategic | H11: Confidentiality agreements signed by the potential strategic buyers of the outreach wave less G&W (recorded individually at R011); the agreements contained no “standstill” or similar provision prohibiting a proposal or offer; the wave’s memorandum was later distributed to signers including Party A, Party B and G&W. | K11: NDA signed (stated cohort; residual after G&W’s individual row, section 5.2). Base: “Each of the potential strategic buyers and 14 potential financial buyers subsequently executed confidentiality agreements” / “did not contain any “standstill” or similar provision that would prohibit a potential buyer from submitting a proposal or making an offer to acquire the Company” The signing wave spans the reported period, so the Working date takes its first day; the memorandum distribution bounds the signings: “the Company prepared a memorandum concerning the Company and its prospects, which was distributed to the potential buyers, including Party A, Party B and G&W, that had executed confidentiality agreements” (P-007). | L11: =HYPERLINK("#Source text!$D$5","P-004; P-007 (main: P-004)") | M11: Q3; Q7 | O11: R009 | P11: Yes | Q11: 10 | R11: 2016-03-28 | S11: 2016-04-22 | T11: 2016-03-28 | U11: Relative only | V11: Assigned: bound | AK11: 28 | AL11: R011 (G&W); R010 (financial residual) | AM11: PWRR-G&W 2016
A12: 10 | B12: from the week of 03/28/2016; by 04/22/2016 | C12: 14 potential financial buyers (of 18 contacted) | D12: NDA signed | E12: 1 | F12: 1 | G12: Financial | H12: Confidentiality agreements signed by 14 of the 18 potential financial buyers contacted in the outreach wave; same no-standstill terms and memorandum distribution. | K12: NDA signed (stated cohort). Quotes: “Each of the potential strategic buyers and 14 potential financial buyers subsequently executed confidentiality agreements” / “did not contain any “standstill” or similar provision that would prohibit a potential buyer from submitting a proposal or making an offer to acquire the Company” Memorandum distribution: “the Company prepared a memorandum concerning the Company and its prospects, which was distributed to the potential buyers, including Party A, Party B and G&W, that had executed confidentiality agreements” (P-007) bounds the signings. | L12: =HYPERLINK("#Source text!$D$5","P-004; P-007 (main: P-004)") | M12: Q3; Q7 | O12: R010 | P12: Yes | Q12: 14 | R12: 2016-03-28 | S12: 2016-04-22 | T12: 2016-03-28 | U12: Relative only | V12: Assigned: bound | AK12: 28 | AL12: R009 (strategic residual) | AM12: PWRR-G&W 2016
A13: 11 | B13: 04/03/2016 | C13: G&W (Genesee & Wyoming Inc.) | D13: NDA signed | E13: 1 | F13: 1 | G13: Strategic | H13: Acquisition-related confidentiality agreement between the Company and G&W dated 04/03/2016 (the merger agreement’s defined “Confidentiality Agreement”); G&W also met management at the 2016 Connections Convention (04/03–04/06) and received the memorandum. | K13: NDA signed (stated): the merger agreement definition fixes G&W’s individual date and the wave cohort rows (R009–R010) exclude it. Quotes: “shall mean the Confidentiality Agreement between the Company and Parent dated April 3, 2016” / “including Party A, Party B and G&W, that had executed confidentiality agreements” | L13: =HYPERLINK("#Source text!$D$31","X-001; P-007 (main: X-001)") | M13: Q3 | O13: R011 | P13: Yes | Q13: 1 | R13: 2016-04-03 | S13: 2016-04-03 | T13: 2016-04-03 | U13: Reported day | V13: Reported | AK13: A-48 | AL13: R009/R010 (wave cohorts) | AM13: PWRR-G&W 2016
A14: 12 | B14: 04/03/2016–04/06/2016 | C14: Five unnamed potential strategic buyers (incl. G&W) | D14: Information access changed | E14: 1 | F14: 1 | G14: Strategic | H14: GHF and Company management held a series of introductory management meetings with five potential strategic buyers (incl. G&W) at the American Short Line and Regional Railroad Association’s 2016 Connections Convention; the 14 financial-signer bidders and other NDA signers received no comparable management meetings at that time; the meetings were venue-based (no selection reason stated for the five). Count blank (access row). | K14: Information access changed (classification): management meetings given to some live bidders and not others, recorded once for the access decision (not per meeting). Quote: “held a series of introductory meetings with five potential strategic buyers (including G&W) at the American Short Line and Regional Railroad Association’s 2016 Connections Convention” | L14: =HYPERLINK("#Source text!$D$6","P-005 (main: P-005)") | M14: Q1 | O14: R012 | P14: Yes | R14: 2016-04-03 | S14: 2016-04-06 | T14: 2016-04-03 | U14: Reported interval | V14: Assigned: bound | AK14: 28 | AM14: PWRR-G&W 2016
A15: 13 | B15: 04/07/2016 | C15: Transaction Committee | D15: Target decision | E15: 1 | F15: 1 | H15: Authorized GHF to contact the five convention parties, other potential strategic buyers (including certain Class I railroads) and private equity firms under NDA to confirm their continuing interest. | K15: Target decision (stated). Quote: “the Transaction Committee authorized representatives of GHF, on behalf of the Company, to contact each of the five interested parties with whom management had met at the 2016 Connections Convention, as well as other potential strategic buyers (including certain Class I railroads) and private equity firms who had entered into confidentiality agreements with the Company to confirm their continuing interest” | L15: =HYPERLINK("#Source text!$D$7","P-006 (main: P-006)") | O15: R013 | P15: Yes | R15: 2016-04-07 | S15: 2016-04-07 | T15: 2016-04-07 | U15: Reported day | V15: Reported | AK15: 28 | AM15: PWRR-G&W 2016
A16: 14 | B16: by 04/07/2016; day not disclosed | C16: Two unnamed additional Class I railroads | D16: Contact | E16: 1 | F16: 1 | G16: Strategic | H16: Approached by the Company (management) before the 04/07/2016 committee report to gauge interest in a possible transaction; no NDA, bid or further participation reported; they never entered the process (no outcome row). Count 2 = cohort size. | K16: Contact (stated): “Mr. Noreck reported that the Company had also approached two additional Class I railroads to determine their interest in a possible transaction” Direction: target-to-bidder; the approach precedes the 04/07/2016 meeting (day not disclosed), so the bound is the report date. | L16: =HYPERLINK("#Source text!$D$7","P-006 (main: P-006)") | O16: R014 | P16: Yes | Q16: 2 | S16: 2016-04-07 | T16: 2016-04-07 | U16: Relative only | V16: Assigned: bound | AK16: 28 | AM16: PWRR-G&W 2016
A17: 15 | B17: 04/21/2016 | C17: Party B | D17: Contact | E17: 1 | F17: 1 | G17: Strategic | H17: Introductory meeting held by the Company and GHF with Party B; first individually recorded meeting for Party B. Repeat contact: Party B is treated as one of the contacted NDA signers of the March wave (R007/R009), so Count 0; the alternative reading is flagged in Q5. | K17: Contact (stated), repeat within the wave. Quote: “Subsequently, on April 21, 2016, the Company and representatives of GHF held an introductory meeting with another potential strategic buyer” | L17: =HYPERLINK("#Source text!$D$7","P-006 (main: P-006)") | M17: Q5 | O17: R015 | P17: Yes | Q17: 0 | R17: 2016-04-21 | S17: 2016-04-21 | T17: 2016-04-21 | U17: Reported day | V17: Reported | AK17: 28 | AM17: PWRR-G&W 2016
A18: 16 | B18: by 04/27/2016; IOI deadline 05/10/2016 | C18: Process (all potential buyers) | D18: Deadline set | E18: 1 | F18: 1 | H18: Each potential buyer advised to submit a non-binding indication of interest by 05/10/2016; the advice is reported at the 04/27/2016 executive session of the Board; deadline version 1 (later revised, R017). Communication day not disclosed. | K18: Deadline set (stated); known only by the 04/27/2016 report. Quote: “each potential buyer had been advised to submit a non-binding indication of interest by May 10, 2016” This date was superseded before arrival, so it stays in the set/revised history with no milestone row. | L18: =HYPERLINK("#Source text!$D$8","P-007 (main: P-007)") | M18: Q2 | O18: R016 | P18: Yes | S18: 2016-04-27 | T18: 2016-04-27 | U18: Relative only | V18: Assigned: bound | AE18: 2016-05-10 | AK18: 29 | AM18: PWRR-G&W 2016
A19: 17 | B19: after 04/27/2016; day not disclosed (new deadline 05/19/2016) | C19: Process (all potential buyers) | D19: Deadline revised | E19: 1 | F19: 1 | H19: IOI deadline postponed from 05/10/2016 to 05/19/2016 to ensure potential buyers had sufficient time to formulate their most compelling offers; requester not disclosed; all potential buyers affected. Treatment: Extended — this row moved the 05/10/2016 due date (recorded here and in the Summary map). | K19: Deadline revised (stated). Quote: “which deadline was subsequently postponed to May 19, 2016 to ensure the potential buyers had sufficient time to formulate their most compelling offers” Revision day not disclosed; window 04/27–05/19 bounded by the 04/27 report and the new due date; midpoint assigned. | L19: =HYPERLINK("#Source text!$D$8","P-007 (main: P-007)") | M19: Q2; Q7 | O19: R017 | P19: Yes | R19: 2016-04-27 | S19: 2016-05-19 | T19: 2016-05-08 | U19: Relative only | V19: Assigned: midpoint | AE19: 2016-05-19 | AF19: Extended | AK19: 29 | AL19: moves R016 (05/10) to 05/19 | AM19: PWRR-G&W 2016
A20: 18 | B20: 05/19/2016 | C20: Process (all potential buyers) | D20: Deadline | E20: 1 | F20: 1 | H20: IOI deadline reached while operative; nine IOIs were received between 05/19 and 06/01 (a window that straddles the due date, so no submission is treated as late) and the committee took its next step on the bids in hand (05/23 and 06/01 reviews; exclusions and advancement). Treatment: Enforced. | K20: Deadline (stated milestone; treatment convention). Quotes: “Between May 19, 2016 and June 1, 2016, the Company received nine written indications of interest” / “the Transaction Committee concluded that the two low bidders should be excluded from that process. The Transaction Committee authorized representatives of GHF to schedule in-person management presentations with the remaining seven potential buyers” | L20: =HYPERLINK("#Source text!$D$9","P-008 (main: P-008)") | M20: Q2 | O20: R018 | P20: Yes | R20: 2016-05-19 | S20: 2016-05-19 | T20: 2016-05-19 | U20: Reported day | V20: Reported | AE20: 2016-05-19 | AF20: Enforced | AK20: 29 | AM20: PWRR-G&W 2016
A21: 19 | B21: 05/19/2016–06/01/2016 | C21: Nine IOI submitters (anonymous cohort) | D21: Bid | E21: 1 | F21: 1 | G21: Unknown | H21: Nine written non-binding indications of interest at $17.93–$26.50 per share (as-converted; group envelope across the cohort, not any member’s price), implying equity values of $90–134 million; made before substantive diligence access (no data site before the 06/01/2016 advancement), so Heavy by context. Parties B, D, E, F and G&W and the two excluded low bidders fall within this cohort’s stage; Party C’s IOI came separately in Round 2 (R025). Type: Unknown — the cohort mixes strategic and financial bidders (split not supplied at this stage). | I21: Informal | J21: Heavy | K21: Bid (stated cohort; group-envelope convention, section 9.4). Quote: “Between May 19, 2016 and June 1, 2016, the Company received nine written indications of interest (“IOIs”) from potential buyers, with offer prices per share ranging from $17.93 to $26.50 (assuming the conversion of preferred stock into common stock), implying equity values of $90 million to $134 million” Formality: written non-binding indications; no returned agreement document or other formal signal at this stage → Informal. Conditions: preliminary non-binding indications made before substantive diligence access → Heavy by context. | L21: =HYPERLINK("#Source text!$D$9","P-008 (main: P-008)") | M21: Q6; Q7; Q8 | O21: R019 | P21: Yes | Q21: 9 | R21: 2016-05-19 | S21: 2016-06-01 | T21: 2016-05-19 | U21: Reported interval | V21: Assigned: deadline | W21: 17.93 | X21: 26.5 | Y21: Group envelope | Z21: Stated | AA21: USD | AB21: Not stated | AD21: Fin: not stated; DD required: not stated; DD open: no; Excl: not stated | AK21: 29 | AM21: PWRR-G&W 2016
A22: 20 | B22: by 05/19/2016 | C22: 16 remaining NDA signers (of the 25) | D22: Did not submit | E22: 1 | F22: 1 | G22: Unknown | H22: Inferred: residual — 25 NDA signers (11 strategic + 14 financial) − 9 IOI submitters = 16 non-submitters at the 05/19/2016 IOI deadline. Includes the wave’s silent signers never individually mentioned again; Party A may also sit here (see R035). Type: Unknown — type split of the residual is not supplied. | K22: Inferred: residual (section 10.2). Base: “Each of the potential strategic buyers and 14 potential financial buyers subsequently executed confidentiality agreements” (25); accounted submitters: nine IOIs (R019). No other stated exits, and the next transition names the continuing seven as all within the nine. Supporting quote: “Between May 19, 2016 and June 1, 2016, the Company received nine written indications of interest”. | L22: =HYPERLINK("#Source text!$D$5","P-004; P-008 (main: P-004)") | M22: Q4 | O22: R020 | P22: Yes | Q22: 16 | S22: 2016-05-19 | T22: 2016-05-19 | U22: Relative only | V22: Assigned: deadline | AH22: Unknown | AI22: Not stated | AJ22: Inferred: residual | AK22: 28 | AL22: base R009–R011; covered submitters R019 | AM22: PWRR-G&W 2016
A23: 21 | B23: 06/01/2016 (decision concluded at the 06/01/2016 meeting; meetings also 05/23/2016) | C23: Transaction Committee | D23: Target decision | E23: 1 | F23: 1 | H23: Concluded that the two low bidders should be excluded from the management-presentation process and authorized in-person management presentations with the remaining seven potential buyers plus additional due diligence and access to an internet data site for legal and financial due diligence. | K23: Target decision (stated). Considered at the 05/23 and 06/01/2016 meetings; Working date = last meeting day (Assigned: decision day). Quotes: “In view of the substantial amount of management time that would be required for management presentations, the Transaction Committee concluded that the two low bidders should be excluded from that process. The Transaction Committee authorized representatives of GHF to schedule in-person management presentations with the remaining seven potential buyers and allow these parties to conduct additional due diligence” / “given access to an internet data site to conduct legal and financial due diligence” | L23: =HYPERLINK("#Source text!$D$9","P-008 (main: P-008)") | M23: Q1 | O23: R021 | P23: Yes | R23: 2016-05-23 | S23: 2016-06-01 | T23: 2016-06-01 | U23: Reported interval | V23: Assigned: decision day | AK23: 29 | AL23: exclusions R022; advancement covered here | AM23: PWRR-G&W 2016
A24: 22 | B24: 06/01/2016 (decision concluded; meetings 05/23 and 06/01/2016) | C24: Two unnamed low bidders (of the nine IOI submitters) | D24: Dropped by target | E24: 1 | F24: 1 | G24: Unknown | H24: Excluded from the management-presentation and data-site stage as the two lowest-priced IOIs; stage left: Round 1 advancement; their IOIs remain among the nine received. Decided by: Target; Exit reason: Lower offer than rivals. Type: Unknown — split not supplied. | K24: Dropped by target (stated): the target excludes participants that had entered the process. Quote: “the Transaction Committee concluded that the two low bidders should be excluded from that” Being the two lowest is the stated reason (Lower offer than rivals); no price comparison of individual bids is disclosed. | L24: =HYPERLINK("#Source text!$D$9","P-008 (main: P-008)") | M24: Q4 | O24: R022 | P24: Yes | Q24: 2 | R24: 2016-05-23 | S24: 2016-06-01 | T24: 2016-06-01 | U24: Reported interval | V24: Assigned: decision day | AH24: Target | AI24: Lower offer than rivals | AJ24: Stated | AK24: 29 | AL24: selection R021; stage R019 | AM24: PWRR-G&W 2016
A25: 23 | B25: mid-June 2016 | C25: Process (Round 2) | D25: Round opened | E25: 1 | F25: 2 | H25: LOI stage: GHF instructed all potential buyers to submit non-binding LOIs by 07/20/2016, together with mark-ups of the forms of merger agreement, disclosure letter and voting agreement (posted to the data site 06/29, 06/30 and 07/11/2016); valuation requested on the basis of 100% of the outstanding common on a dollar-per-share basis as-converted, or the financial terms of any non-cash proposal; management presentations and data-site diligence ran through June–July (status update 06/30/2016); the Due date is carried on this row. Round finality: Inferred final — no final-stage announcement, but the round closed when the target moved to confirmatory due diligence and definitive negotiation with selected bidders (07/27/2016). | K25: Round opened (analytical/convention): a distinct drafting-and-information stage linked to new offers (section 6.3). Alternative boundary 06/01/2016 (advancement) rejected because no updated offers were sought then (Q1). Quotes: “In mid-June 2016, at the direction of the Transaction Committee, representatives of GHF instructed all potential buyers to submit non-binding letters of intent (“LOIs”) by July 20, 2016, together with mark-ups of the forms of merger agreement, disclosure letter and voting agreement, which GHF indicated would be posted to the internet data site” / “Potential buyers were instructed to provide a valuation for the Company based on the purchase of 100% of the outstanding common stock on a dollar per share basis (assuming conversion of the preferred stock into common stock) or the financial terms of any non-cash proposal” | L25: =HYPERLINK("#Source text!$D$10","P-009 (main: P-009)") | M25: Q1 | O25: R023 | P25: Yes | R25: 2016-06-11 | S25: 2016-06-19 | T25: 2016-06-15 | U25: Approximate window | V25: Assigned: midpoint | AE25: 2016-07-20 | AG25: Inferred final | AK25: 29 | AL25: candidate boundary R021 (06/01, rejected) | AM25: PWRR-G&W 2016
A26: 24 | B26: early July 2016 | C26: Party C | D26: NDA signed | E26: 1 | F26: 2 | G26: Strategic | H26: Late-entrant strategic buyer that approached the Company’s management in early July 2016 and executed a confidentiality agreement before receiving the memorandum provided to the other potential buyers. | K26: NDA signed (stated): “In early July 2016, a potential strategic buyer that had not previously been part of the process” / “After executing a confidentiality agreement, Party C was provided the memorandum concerning the Company provided to the other potential buyers” Day not disclosed (early-July band); midpoint assigned. Note: the Board’s reasons state 25 confidentiality agreements in total (Q3 reconciliation). | L26: =HYPERLINK("#Source text!$D$12","P-011 (main: P-011)") | M26: Q3 | O26: R024 | P26: Yes | Q26: 1 | R26: 2016-07-01 | S26: 2016-07-10 | T26: 2016-07-05 | U26: Approximate window | V26: Assigned: midpoint | AK26: 29 | AL26: R025 (IOI); R026 (catch-up access) | AM26: PWRR-G&W 2016
A27: 25 | B27: 07/12/2016 | C27: Party C | D27: Bid | E27: 1 | F27: 2 | G27: Strategic | H27: IOI at $21.00 per share (as-converted), implying an equity value of $108 million; non-binding and made on the memorandum only (data-site access followed), so Heavy by context; first Party C bid in Round 2. | I27: Informal | J27: Heavy | K27: Bid (stated). Quote: “On July 12, 2016, Party C submitted an IOI with an offer price per share of $21.00 (implying an equity value of $108 million)” Formality: non-binding indication with no returned agreement document → Informal. Conditions: pre-substantive-diligence indication (memorandum only) → Heavy by context. | L27: =HYPERLINK("#Source text!$D$12","P-011 (main: P-011)") | M27: Q6 | O27: R025 | P27: Yes | Q27: 1 | R27: 2016-07-12 | S27: 2016-07-12 | T27: 2016-07-12 | U27: Reported day | V27: Reported | W27: 21 | X27: 21 | Y27: Point | Z27: Stated | AA27: USD | AB27: Not stated | AD27: Fin: not stated; DD required: not stated; DD open: no; Excl: not stated | AK27: 29 | AM27: PWRR-G&W 2016
A28: 26 | B28: 07/12/2016–07/14/2016 (memorandum earlier, early July) | C28: Party C | D28: Information access changed | E28: 1 | F28: 2 | G28: Strategic | H28: Late-entrant catch-up access: after its NDA Party C received the memorandum; after its 07/12/2016 IOI it was given access to the internet data site and a telephone management presentation (07/14/2016) while other buyers’ diligence was under way; no comparable catch-up accommodation for other late parties is disclosed. Count blank (access row). | K28: Information access changed (late entrant’s catch-up access, section 4), recorded once. Quote: “Subsequently, Party C was provided access to the internet data site and the Company’s management held a management presentation with Party C by telephone on July 14, 2016” | L28: =HYPERLINK("#Source text!$D$12","P-011 (main: P-011)") | M28: Q1 | O28: R026 | P28: Yes | R28: 2016-07-12 | S28: 2016-07-14 | T28: 2016-07-12 | U28: Reported interval | V28: Assigned: bound | AK28: 29 | AL28: R024 (NDA), R025 (IOI) | AM28: PWRR-G&W 2016
A29: 27 | B29: 07/20/2016 | C29: Process (all potential buyers) | D29: Deadline | E29: 1 | F29: 2 | H29: LOI deadline reached; six LOIs were received in late July 2016 (G&W’s dated 07/21/2016) and were considered without any revision of the due date. Treatment: Late bids accepted. | K29: Deadline (stated; treatment convention). Quotes: “In late July 2016, the Company received six LOIs with offer prices per share ranging from $19.20 to $24.00” / “G&W submitted an LOI on July 21, 2016 to acquire the Company for a price of $21.15 per share (subject to a three-week exclusive diligence period)” A bid dated after the 07/20/2016 due date was considered without a revision → Late bids accepted (not Enforced). | L29: =HYPERLINK("#Source text!$D$13","P-012; P-014 (main: P-012)") | M29: Q2 | O29: R027 | P29: Yes | R29: 2016-07-20 | S29: 2016-07-20 | T29: 2016-07-20 | U29: Reported day | V29: Reported | AE29: 2016-07-20 | AF29: Late bids accepted | AK29: 29 | AM29: PWRR-G&W 2016
A30: 28 | B30: late July 2016 | C30: Party B | D30: Bid | E30: 1 | F30: 2 | G30: Strategic | H30: LOI at $24.00 per share (as-converted; point), subject to an expedited diligence review; returned mark-ups of the merger agreement and voting agreement with the LOI; highest of the six LOIs; consideration form not stated. | I30: Formal | J30: Light | K30: Bid (stated). Quotes: “Party B submitted an LOI to acquire the Company for a price of $24.00 per share (subject to an expedited diligence review)” / “Party B, G&W and another bidder (“Party D”) also provided mark-ups of the draft merger agreement and voting agreement” Formality: bidder-returned agreement and voting-agreement markups (strong signal 1) → Formal. Conditions: expedited diligence and final documentation only, no Heavy trigger → Light. | L30: =HYPERLINK("#Source text!$D$13","P-012; P-013 (main: P-012)") | M30: Q6 | O30: R028 | P30: Yes | Q30: 1 | R30: 2016-07-20 | S30: 2016-07-31 | T30: 2016-07-20 | U30: Approximate window | V30: Assigned: deadline | W30: 24 | X30: 24 | Y30: Point | Z30: Stated | AA30: USD | AB30: Not stated | AD30: Fin: not stated; DD required: confirmatory; DD open: yes; Excl: not stated | AK30: 29 | AM30: PWRR-G&W 2016
A31: 29 | B31: late July 2016 | C31: Party E | D31: Bid | E31: 1 | F31: 2 | G31: Strategic | H31: LOI at $21.26 per share (as-converted; point), subject to a 60-day exclusivity period for due diligence and negotiation of definitive documentation; provided a summary of material issues and proposed changes to the merger agreement and voting agreement instead of mark-ups. | I31: Informal | J31: Heavy | K31: Bid (stated). Quotes: “Party E (a strategic buyer) submitted an LOI to acquire the Company for a price of $21.26 per share (subject to a 60-day exclusivity period for due diligence and negotiation of definitive documentation)” / “One bidder (“Party E”) provided a summary of material issues and proposed changes to the merger agreement and voting agreement with respect to those issues” Formality: an issues summary is not a returned agreement markup and no other formal signal is reported → Informal under the working default (borderline; Q6). Conditions: stated exclusive, multi-week diligence period → Heavy. | L31: =HYPERLINK("#Source text!$D$16","P-015; P-012 (main: P-015)") | M31: Q6 | O31: R029 | P31: Yes | Q31: 1 | R31: 2016-07-20 | S31: 2016-07-31 | T31: 2016-07-20 | U31: Approximate window | V31: Assigned: deadline | W31: 21.26 | X31: 21.26 | Y31: Point | Z31: Stated | AA31: USD | AB31: Not stated | AD31: Fin: not stated; DD required: substantive (60 days); DD open: yes; Excl: requested (60 days) | AK31: 30 | AM31: PWRR-G&W 2016
A32: 30 | B32: late July 2016 | C32: Party D | D32: Bid | E32: 1 | F32: 2 | G32: Financial | H32: LOI at $21.00 per share (as-converted; point), subject to a four-week diligence period; returned mark-ups of the merger agreement and voting agreement. | I32: Formal | J32: Heavy | K32: Bid (stated). Quotes: “Party D (a financial buyer) submitted an LOI to acquire the Company for a price of $21.00 per share (subject to a four-week diligence period)” / “Party B, G&W and another bidder (“Party D”) also provided mark-ups of the draft merger agreement and voting agreement” Formality: bidder-returned markups → Formal. Conditions: stated multi-week diligence period → Heavy. | L32: =HYPERLINK("#Source text!$D$17","P-016; P-012 (main: P-016)") | M32: Q6 | O32: R030 | P32: Yes | Q32: 1 | R32: 2016-07-20 | S32: 2016-07-31 | T32: 2016-07-20 | U32: Approximate window | V32: Assigned: deadline | W32: 21 | X32: 21 | Y32: Point | Z32: Stated | AA32: USD | AB32: Not stated | AD32: Fin: not stated; DD required: substantive (4 wks); DD open: yes; Excl: not stated | AK32: 30 | AM32: PWRR-G&W 2016
A33: 31 | B33: late July 2016 | C33: Party C | D33: Bid | E33: 1 | F33: 2 | G33: Strategic | H33: LOI at $19.30 per share (as-converted; point), subject to a 30-day diligence period; revises Party C’s 07/12/2016 IOI of $21.00 (R025). | I33: Informal | J33: Heavy | K33: Bid (stated), second Party C bid in Round 2, so Count 0 (section 7.2). Quote: “Party C submitted an LOI to acquire the Company for a price of $19.30 per share (subject to a 30-day diligence period)” Formality: no returned agreement document → Informal. Conditions: stated 30-day diligence period → Heavy. | L33: =HYPERLINK("#Source text!$D$18","P-017 (main: P-017)") | M33: Q6 | O33: R031 | P33: Yes | Q33: 0 | R33: 2016-07-20 | S33: 2016-07-31 | T33: 2016-07-20 | U33: Approximate window | V33: Assigned: deadline | W33: 19.3 | X33: 19.3 | Y33: Point | Z33: Stated | AA33: USD | AB33: Not stated | AD33: Fin: not stated; DD required: substantive (30 days); DD open: yes; Excl: not stated | AK33: 30 | AL33: revises R025 | AM33: PWRR-G&W 2016
A34: 32 | B34: late July 2016 | C34: Party F | D34: Bid | E34: 1 | F34: 2 | G34: Strategic | H34: LOI at $19.20 per share (as-converted; point), subject to a 30-day due diligence period; lowest of the six LOIs. | I34: Informal | J34: Heavy | K34: Bid (stated). Quote: “Party F (a strategic buyer) submitted an LOI to acquire the Company for a price of $19.20 per share (subject to a 30-day due diligence period)” Formality: no returned agreement document → Informal. Conditions: stated 30-day diligence period → Heavy. | L34: =HYPERLINK("#Source text!$D$19","P-018 (main: P-018)") | M34: Q6 | O34: R032 | P34: Yes | Q34: 1 | R34: 2016-07-20 | S34: 2016-07-31 | T34: 2016-07-20 | U34: Approximate window | V34: Assigned: deadline | W34: 19.2 | X34: 19.2 | Y34: Point | Z34: Stated | AA34: USD | AB34: Not stated | AD34: Fin: not stated; DD required: substantive (30 days); DD open: yes; Excl: not stated | AK34: 30 | AM34: PWRR-G&W 2016
A35: 33 | B35: by 07/20/2016 | C35: One unnamed strategic bidder (of the seven advancing) | D35: Did not submit | E35: 1 | F35: 2 | G35: Strategic | H35: Elected not to submit an LOI in the 07/20/2016 solicitation despite advancing to management presentations and data-site diligence; Decided by: Bidder; not necessarily a permanent withdrawal. Count 1 = the one unnamed strategic non-submitter. | K35: Did not submit (stated): “One strategic buyer and one financial buyer elected not to submit an LOI” The two non-submitters are the arithmetic remainder of the seven advancing bidders after the five of them that submitted LOIs; the six-LOI receipt is reported at “In late July 2016, the Company received six LOIs with offer prices per share ranging from $19.20 to $24.00” (P-012). | L35: =HYPERLINK("#Source text!$D$13","P-012; P-019 (main: P-012)") | M35: Q4 | O35: R033 | P35: Yes | Q35: 1 | S35: 2016-07-20 | T35: 2016-07-20 | U35: Relative only | V35: Assigned: deadline | AH35: Bidder | AI35: Not stated | AJ35: Stated | AK35: 29 | AM35: PWRR-G&W 2016
A36: 34 | B36: by 07/20/2016 | C36: One unnamed financial bidder (of the seven advancing) | D36: Did not submit | E36: 1 | F36: 2 | G36: Financial | H36: Elected not to submit an LOI in the 07/20/2016 solicitation despite advancing to management presentations and data-site diligence; Decided by: Bidder; not necessarily a permanent withdrawal. Count 1 = the one unnamed financial non-submitter. | K36: Did not submit (stated): “One strategic buyer and one financial buyer elected not to submit an LOI” The six-LOI receipt is reported at “In late July 2016, the Company received six LOIs with offer prices per share ranging from $19.20 to $24.00” (P-012). | L36: =HYPERLINK("#Source text!$D$13","P-012; P-019 (main: P-012)") | M36: Q4 | O36: R034 | P36: Yes | Q36: 1 | S36: 2016-07-20 | T36: 2016-07-20 | U36: Relative only | V36: Assigned: deadline | AH36: Bidder | AI36: Not stated | AJ36: Stated | AK36: 29 | AM36: PWRR-G&W 2016
A37: 35 | B37: by 07/20/2016 | C37: Party A (identity row) | D37: Did not submit | E37: 1 | F37: 2 | G37: Strategic | H37: Inferred: identity — Party A is not among the six named LOI submitters, the first continuing set the filing identifies by name; the row records only that Party A was out by this transition, not which anonymous exit was its own. Count 0. Covering cohorts that could already count it: R033 (unnamed strategic LOI non-submitter — recommended reading), R020 (16 residual non-submitters, which would place it at 05/19/2016), R022 (two low bidders). See Q4/Q5. No counts moved from a cohort to this name. | K37: Inferred: identity (section 10.2): Party A is introduced in Q4 2015, named among the memorandum recipients, and never mentioned again; the first named continuing set without it is the six LOI submitters: “In late July 2016, the Company received six LOIs with offer prices per share ranging from $19.20 to $24.00” (P-012). Other quotes: “including Party A, Party B and G&W, that had executed confidentiality agreements” / “proceed with confirmatory due diligence and negotiations with G&W and Party B because of the higher offers made by each of G&W and Party B relative to the other potential buyers” | L37: =HYPERLINK("#Source text!$D$8","P-007; P-012; P-020 (main: P-007)") | M37: Q4; Q5 | O37: R035 | P37: Yes | Q37: 0 | S37: 2016-07-20 | T37: 2016-07-20 | U37: Relative only | V37: Assigned: deadline | AH37: Unknown | AI37: Not stated | AJ37: Inferred: identity | AK37: 28 | AM37: PWRR-G&W 2016
A38: 36 | B38: 07/21/2016 | C38: G&W | D38: Bid | E38: 1 | F38: 2 | G38: Strategic | H38: LOI at $21.15 per share (as-converted; point) = $20.02 cash at closing plus a $1.13 contingent value right tied to the subsequent sale of the Company’s South Quay property (cash-settled CVR; payoff uncertain), subject to a three-week exclusive diligence period; also returned a mark-up of the disclosure letter; submitted one day after the 07/20/2016 due date. | I38: Formal | J38: Heavy | K38: Bid (stated; the payment split is preserved). Quotes: “G&W submitted an LOI on July 21, 2016 to acquire the Company for a price of $21.15 per share (subject to a three-week exclusive diligence period). The price included $20.02 cash at closing and $1.13 in the form of a contingent value right, the value of which was based on the subsequent sale of the Company’s South Quay property” / “G&W also provided a mark-up of the disclosure letter” Formality: returned transaction-document markup plus engagement with definitive terms → Formal. Conditions: stated three-week exclusive diligence period → Heavy. All cash: Yes (cash plus a contingent cash payment). | L38: =HYPERLINK("#Source text!$D$15","P-014 (main: P-014)") | M38: Q6; Q8 | O38: R036 | P38: Yes | Q38: 1 | R38: 2016-07-21 | S38: 2016-07-21 | T38: 2016-07-21 | U38: Reported day | V38: Reported | W38: 21.15 | X38: 21.15 | Y38: Point | Z38: Stated | AA38: USD | AB38: Yes | AC38: 20.02 | AD38: Fin: not stated; DD required: substantive (3 wks); DD open: yes; Excl: requested (3 wks) | AK38: 29 | AL38: revised by R037 | AM38: PWRR-G&W 2016
A39: 37 | B39: 07/26/2016 | C39: G&W | D39: Bid | E39: 1 | F39: 2 | G39: Strategic | H39: Revised LOI at $22.15 per share (as-converted; point) = $21.02 cash plus the unchanged $1.13 South Quay CVR, submitted after GHF feedback that its price and CVR structure were not competitive; second G&W bid in Round 2, so Count 0. | I39: Formal | J39: Heavy | K39: Bid (stated price revision; section 9.1 keeps revisions as Bid rows). Quote: “On July 26, 2016, in response to feedback from representatives of GHF indicating its price and CVR structure were not competitive, G&W submitted a revised LOI, which increased its offer to $22.15 per share” Conditions unchanged: three-week exclusive diligence period → Heavy. | L39: =HYPERLINK("#Source text!$D$15","P-014 (main: P-014)") | M39: Q6; Q8 | O39: R037 | P39: Yes | Q39: 0 | R39: 2016-07-26 | S39: 2016-07-26 | T39: 2016-07-26 | U39: Reported day | V39: Reported | W39: 22.15 | X39: 22.15 | Y39: Point | Z39: Stated | AA39: USD | AB39: Yes | AC39: 21.02 | AD39: Fin: not stated; DD required: substantive (3 wks); DD open: yes; Excl: requested (3 wks) | AK39: 29 | AL39: revises R036 | AM39: PWRR-G&W 2016
A40: 38 | B40: 07/27/2016 | C40: Transaction Committee (in person after the regular quarterly Board meeting) | D40: Target decision | E40: 1 | F40: 2 | H40: Concluded that the Company should proceed with confirmatory due diligence and negotiations with G&W and Party B because of their higher offers, and directed that the remaining bidders be told they were no longer involved; independent directors updated (Director Smith recused because GATX Corporation, which he serves and which holds 4.92% of the common stock, might be a potential buyer). | K40: Target decision (stated): selection of two finalists and exclusion of the rest in one shared decision. Quotes: “The Transaction Committee concluded that the Company should proceed with confirmatory due diligence and negotiations with G&W and Party B because of the higher offers made by each of G&W and Party B relative to the other potential buyers” / “representatives of GHF subsequently contacted the remaining bidders to inform them that they were no longer involved in the process” / “Director Smith is Vice President and Group Executive, Locomotive Group of GATX Corporation (“GATX”), which owns 4.92% of the Company’s common stock. In order to avoid any potential conflict, Mr. Smith elected to recuse himself from participating in this and other Board meetings at which the bidding process and any potential transaction were to be discussed because of the possibility that GATX might be a potential buyer of the Company” | L40: =HYPERLINK("#Source text!$D$21","P-020 (main: P-020)") | M40: Q1 | O40: R038 | P40: Yes | R40: 2016-07-27 | S40: 2016-07-27 | T40: 2016-07-27 | U40: Reported day | V40: Reported | AK40: 30 | AL40: closes R023; drops R039–R042; R043 | AM40: PWRR-G&W 2016
...

Sheet Summary
A1: PWRR × G&W — deal ledger summary (Providence and Worcester Railroad Company / Genesee & Wyoming Inc., 2016)
A2: 1. Status and commercial account
A3: Delivery status | B3: AI first pass; not human-approved. Instruction: SEC_Deal_Ledger_Extraction_Instruction.md, revision of 19 September 2026 (short form). Supplied source: providence-worcester_2016-09-20_DEFM14A.htm — PWRR definitive proxy statement (DEFM14A) filed 09/20/2016, proxy dated 09/19/2016. Source coverage: the complete “Background of the Merger” (pp. 27–32) is reproduced in order in the Source text sheet (P-001–P-029), with every other passage used as X-001 onward.
A4: Commercial account | B4: Initiation was mixed: a Q4 2015 approach by a Class I rail partner (Party A) expressing interest in acquiring equity led, through the Board’s banker search and its 03/14/2016 decision to explore a change of control, to a broad bank-run solicitation of 29 potential buyers (11 strategic, 18 financial) in the week of 03/28/2016. Twenty-five buyers signed confidentiality agreements (no standstills); after introductory meetings and a memorandum, nine submitted non-binding IOIs received 05/19–06/01/2016 at $17.93–$26.50 per share as-converted (equity values $90–134 million), and the committee excluded the two lowest and advanced seven to management presentations and a data site. A mid-June solicitation for LOIs with agreement mark-ups (due 07/20/2016) produced six LOIs in late July at $19.20–$24.00: Party B ($24.00) and G&W ($21.15, then $22.15 including a $1.13 South Quay CVR) led; Party E ($21.26), Party D ($21.00), Party C ($19.30) and Party F ($19.20) followed; one strategic and one financial buyer elected not to submit. On 07/27/2016 the committee chose G&W and Party B for confirmatory due diligence and definitive negotiation and told the remaining bidders they were out; Party D and Party E briefly re-engaged (08/01 revised LOIs of $24.00 and $23.81, Party E supported by Party F financing), but Party D withdrew on 08/02 after the Company declined a no-sign commitment and Party E reverted to $21.26. On 08/12/2016 G&W’s final $25.00 all-cash LOI (CVR dropped, mark-ups returned, expiry 6:00 p.m. 08/13) displaced Party B’s $24.00 after Party B declined to raise, and the Board approved the merger agreement and the Eder Trusts’ voting agreement that same day. Announcement followed on 08/15/2016; no go-shop, competing post-signing proposal, agreement termination or closing is disclosed, STB approval was pending (petition 09/01/2016; voting trust submission 09/14/2016), and closing was expected in Q4 2016.
A5: 2. Deal facts
A6: Target | B6: Providence and Worcester Railroad Company (PWRR), a Rhode Island corporation; regional freight railroad in Massachusetts, Rhode Island, Connecticut and New York; NASDAQ: PWX; US public company. 4,866,593 common shares and 640 preferred shares outstanding on the 09/16/2016 record date (preferred convertible 100-for-1; non-cumulative $5.00 dividend).
A7: Focal acquirer and type | B7: Genesee & Wyoming Inc. (G&W), a Delaware corporation; NYSE: GWR; US public company; Strategic — operating short-line/regional railroad acquirer, buying through its wholly owned shell Pullman Acquisition Sub Inc. (formed 08/12/2016).
A8: Agreed consideration | B8: $25.00 per share in cash (as-converted basis: preferred deemed converted into 100 common shares plus accrued and unpaid dividends); equity awards cashed out at $25.00 (options net of exercise price; RSUs at $25.00); no financing condition; G&W representation as to financial wherewithal. All cash: Yes. No CVR in the signed terms.
A9: Signing | B9: 08/12/2016 — merger agreement among PWRR, G&W and Merger Sub; voting agreement among PWRR, G&W and the Eder Trusts (842,742 common shares, 500 preferred shares).
A10: Announcement | B10: 08/15/2016 — Company press release before the opening of NASDAQ trading.
A11: Completion | B11: Not observed in this filing (expected Q4 2016). Outside dates 12/31/2016, or 02/28/2017 if the only unsatisfied condition is STB approval. Expected closing kept separate from any observed closing.
A12: Termination fee | B12: $3,785,000 payable by the Company to G&W in specified cases (~3% of transaction value; the Company negotiated G&W’s draft down from 3.85%; Party B’s draft was 3% plus its transaction expenses capped at 1%).
A13: Filing identity and date | B13: DEFM14A definitive proxy statement for the special meeting of shareholders (10/26/2016), filed 09/20/2016; background pages 27–32. Source file: raw_filing/providence-worcester_2016-09-20_DEFM14A.htm.
A14: 3. Process and round map
A15: Processes | B15: One sale process (Process 1). No earlier attempt is disclosed (the Q4 2015 Party A approach is round 0, not a separate process); no second process, go-shop or agreement termination is disclosed. Post-signing ledger content is publicity only (R057); the STB process and the 09/06/2016 BMO conflict confirmation sit in these Summary blocks.
A16: Round 0 (pre-solicitation) | B16: R001 Party A interest (Q4 2015); R002 GHF adviser engaged (01/27/2016); R003 sale-strategy decision (03/14/2016); R004 Party A management meetings (03/22–03/23); R005 contact authorization (03/24); R006 Hinckley Allen shown acting (03/24). No Round opened row for round 0.
A17: Round 1 (week of 03/28 – 06/01/2016) | B17: R008 anchor = first outreach wave — 29 potential buyers contacted (R007); rejected candidate anchors R003 and R005. NDA wave R009–R011 (25 signers: 10 remaining strategic + 14 financial + G&W individually; no standstills). Access/differentiation: R012 (convention meetings), R013 (04/07 contact authorization), R014 (two additional Class I railroads contacted). Deadline history: R016 (05/10 set by 04/27), R017 (revised to 05/19), R018 (05/19; Enforced). Bids: R019 (nine IOIs, envelope $17.93–$26.50). Outcomes: R020 (16 residual non-submitters, inferred), R021 (06/01 decision), R022 (two low bidders dropped). Round-bidder tally: 9. Finality: Not final.
A18: Round 2 (mid-June – 07/27/2016) | B18: R023 opened the LOI stage (due 07/20/2016; mark-ups and draft documents posted to the data site 06/29–07/11). Late entrant Party C: R024 NDA, R025 IOI ($21.00), R026 catch-up access. Bids: R028–R032 (B $24.00, E $21.26, D $21.00, C $19.30, F $19.20) and R036–R037 (G&W $21.15, then $22.15). Deadline: R027 (07/20; Late bids accepted). Outcomes: R033–R034 (two non-submitters), R035 (Party A identity row), R038 (07/27 selection of G&W and Party B), R039–R042 (C, D, E, F dropped). Round-bidder tally: 6. Finality: Inferred final.
A19: Round 3 (07/27 – 08/12/2016) | B19: R043 opened confirmatory due diligence and definitive negotiation with G&W and Party B. Re-entries R044–R045; bids R046–R048; withdrawal R049; access update R050; adviser R051; final bid R052 ($25.00); Board decision R053; signing R054; signing outcomes R055–R056. Round-bidder tally: 3. Finality: Inferred final.
A20: Post-signing | B20: R057 announcement (08/15/2016); no competing proposal, go-shop activity, agreement termination or closing observed. Regulatory: STB petition for exemption filed 09/01/2016 and a voting-trust agreement submitted 09/14/2016 (X-009); outside dates X-010. Adviser conflict: on 09/06/2016 the Board considered BMO’s late disclosure of a ~5% BMO-affiliate lending participation in G&W’s secured syndicated facility and determined it was not material to BMO’s independence (P-029; X-016).
A21: 4. Participants and advisers
A22: G&W | B22: Strategic (operating short-line/regional railroad; acquires through wholly owned shell Merger Sub). First observed 04/03/2016 (NDA R011; convention meeting R012); bids R036 ($21.15 with CVR), R037 ($22.15), R052 ($25.00 cash). Winner — no exit row.
A23: Party A | B23: Strategic (Class I rail partner). First observed Q4 2015 (R001); NDA within R009; memorandum recipient; never mentioned again → Count-0 identity row R035 (Inferred: identity; possible covers R033 recommended, R020, R022). See Q4/Q5.
A24: Party B | B24: Strategic. First individual meeting 04/21/2016 (R015); LOI R028 ($24.00); prioritized for definitive negotiation 08/04/2016; declined to raise on 08/12; Not selected at signing R055 (Would not improve earlier offer).
A25: Party C | B25: Strategic late entrant. NDA R024 (early July); IOI R025 ($21.00); LOI R031 ($19.30); dropped R039 (07/27).
A26: Party D | B26: Financial (as described in the filing). LOI R030 ($21.00); dropped R040; re-entered R044; revised LOI R046 ($24.00); Withdrew R049 (terms/process; no-sign commitment declined).
A27: Party E | B27: Strategic. LOI R029 ($21.26); dropped R041; re-entered R045; revised LOI R047 ($23.81 with Party F financing); reversion R048 ($21.26); Not selected at signing R056.
A28: Party F | B28: Strategic. LOI R032 ($19.20); dropped R042 (07/27 exit); provided financing support to Party E’s withdrawn 08/01 revised proposal (recorded on R047; no re-entry row after its exit).
A29: Anonymous cohorts | B29: Two unnamed low bidders (Unknown type; dropped R022); one unnamed strategic and one unnamed financial non-submitter (R033, R034); 16 residual NDA signers closed by inference at 05/19/2016 (R020); two additional Class I railroads contacted before 04/07/2016 that never entered (R014). Cohorts are not extra parties to add to their members.
A30: Non-bidder holders | B30: The Eder Trusts (shareholders; voting agreement 08/12/2016; X-012/X-024) and GATX Corporation (4.92% common holder; Director Smith recused from process meetings because GATX might be a potential buyer; no contact, NDA or bid disclosed) are not bidders and get no outcome rows.
A31: Advisers | B31: GHF (Greene Holcomb & Fisher LLC) → BMO Capital Markets Corp. — Company financial adviser; engaged 01/27/2016 (R002); GHF’s business acquired by BMO 08/01/2016 (same relationship); aggregate fee ~$2.52 million (X-015); BMO-affiliate lending participation in G&W’s 2015 facility disclosed late and considered not material by the Board on 09/06/2016 (P-029; X-016). Hinckley, Allen & Snyder LLP — Company legal counsel (R006; first shown acting 03/24/2016). Simpson Thacher & Bartlett LLP — G&W legal counsel (R051; first shown acting 08/10/2016). The Company’s STB counsel is unnamed (P-026) and gets no adviser row. Disclosed attributes: PWRR and G&W are US public companies (NASDAQ: PWX; NYSE: GWR); ownership and country of the anonymous parties are not disclosed.
A32: 5. Counts and auction screen
A33: Auction screen | B33: MET — more than one independent prospective acquiring bidder unit executed bidder-target confidentiality agreements for this process (25 in the week-of-03/28 wave plus Party C; G&W among them). No lender-only, adviser or rollover-holder agreements are included; the Eder Trusts’ voting agreement is not a bidder NDA. Extraction proceeds regardless of the screen.
A34: Contacts (ledger tally) | B34: =SUMIFS('Deal ledger'!$Q$3:$Q$100,'Deal ledger'!$D$3:$D$100,"Contact",'Deal ledger'!$P$3:$P$100,"Yes")+SUMIFS('Deal ledger'!$Q$3:$Q$100,'Deal ledger'!$D$3:$D$100,"Bidder interest",'Deal ledger'!$P$3:$P$100,"Yes")
A35: → composition and filing assertions | B35: 31 from Contact rows (29 in the GHF outreach wave + 2 additional Class I railroads approached by the Company) plus 1 from the Party A Bidder interest row, which carries the Q4 2015 first contact = 32 contact units. Party A’s 03/22–03/23 meeting and Party B’s 04/21 meeting are Count 0 repeats. Filing: GHF contacted 11 potential strategic buyers and 18 potential financial buyers (29) in the week of 03/28/2016; the Company also approached two additional Class I railroads (P-004; P-006).
A36: NDA signers (ledger tally) | B36: =SUMIFS('Deal ledger'!$Q$3:$Q$100,'Deal ledger'!$D$3:$D$100,"NDA signed",'Deal ledger'!$P$3:$P$100,"Yes")
A37: → filing assertions and reconciliation | B37: Background: each of the 11 potential strategic buyers and 14 potential financial buyers executed confidentiality agreements (25), plus Party C’s early-July agreement = 26 signatures on the ledger’s reading; the Board’s reasons state “25 of whom entered into confidentiality agreements” (X-002). Q3 reconciles: the reasons’ 25 may exclude Party C or one strategic signer.
A38: IOI submitters | B38: 9 (stated; R019 cohort, envelope $17.93–$26.50; filing: “nine written indications of interest”, P-008).
A39: LOI submitters | B39: 6 (stated; B, G&W, E, D, C, F — R028–R032, R036; plus G&W’s 07/26 revision R037. Filing: “six LOIs”, P-012; group envelope $19.20–$24.00 / $96–121 million).
